Workbook

Sheet README
A1: Standard Design Library: Register
A2: Purpose | B2: Call out approved standard designs (drains, retaining walls, linkways, railings, staircases, POB, USD) quickly for tender drawing preparation, with preliminary quantities.
A4: SHEETS
A5: Design_Selector | B5: Enter requirement (e.g. U-drain 500x800 vehicular, or RW H = 2.8 m) and get the nearest approved design + file links.
A6: Tender_Pack | B6: List the Design IDs used in a tender with lengths. Gives drawing refs, DWG files and preliminary concrete / rebar / formwork / excavation.
A7: Coverage | B7: Shows which sizes / heights have an approved design and where the gaps are (red = 0).
A8: Drain_Register | B8: One row per drain design variant.
A9: RW_Register | B9: One row per retaining wall design variant.
A10: Other_Register | B10: LTA linkway, railing, staircase, POB, USD and others.
A11: Lists | B11: Dropdown values and ID codes. Add new types here.
A13: COLOUR LEGEND
A14: Yellow cell, blue text | B14: Input: type or pick from dropdown.
A15: Grey cell, black text | B15: Formula: do not overwrite.
A16: Green column header | B16: Tender quantity per unit (per m run, or per nr / span where stated).
A17: Green-shaded rows | B17: EXAMPLE data to show the format. Values are illustrative only; delete or overwrite with your own designs.
A19: DESIGN ID FORMAT
A20: Drain | B20: DRN-[Type]-[W]x[D]-[Load]-[Rev] e.g. DRN-UD-0600x0900-VEH-B
A21: Retaining wall | B21: RW-[Type]-H[mm]-S[kPa][-GW]-[Rev] e.g. RW-CANT-H3000-S10-A (-GW = designed with groundwater)
A22: Others | B22: [Family]-[Type]-SP[mm]-H[mm]-[Rev] e.g. LKW-SINGLESPAN-SP6000-H3000-A
A23: Rule | B23: Use the SAME ID for the DWG file name, PDF file name, calc report and the drawing title block.
A25: ADDING A DESIGN
A26: 1 | B26: Fill a new row in the right register. The Design ID builds itself.
A27: 2 | B27: Save the tender detail DWG (xrefs bound / eTransmit, consistent base point and layers) and PDF using that ID as the file name.
A28: 3 | B28: Put the file paths / SharePoint links in the DWG, PDF and Calc columns. Fill quantities per metre.
A29: 4 | B29: Set Status. Only 'Approved' designs appear in the Selector. When revising, set the old row to 'Superseded' and add a new row with the next Rev.
A31: MOVING TO SHAREPOINT / POWER APPS
A32: Tables | B32: Each register is an Excel Table (tblDrain, tblRW, tblOther). In SharePoint: New > List > From Excel, pick the table. Or keep this file in the library and point Power Apps at the tables directly.
A33: Recommended | B33: Import into SharePoint Lists (better for many users, versioning and Power Apps delegation). Keep this workbook as the template and offline copy.
A34: CAD | B34: Sync the SharePoint 'Design Library' document library to your PC (OneDrive Sync), then point AutoCAD Tool Palettes / DesignCenter at the synced folder for drag-and-drop details.
A36: DISCLAIMER | B36: Standard designs are valid only within the stated assumptions. The QP must verify site conditions, loading and soil parameters for each project. Tender quantities are preliminary.

Sheet Design_Selector
A1: Design Selector: find the nearest APPROVED standard design
A2: Type into the yellow cells. Returns the smallest approved design at or above your requirement. Only rows with Status = Approved are considered.
A4: DRAIN | D4: RETAINING WALL
A5: Drain Type | B5: U-Drain | D5: Wall Type | E5: Cantilever RC
A6: Min. Internal Width (mm) | B6: 500 | D6: Retained Height (m) | E6: 2.8
A7: Min. Internal Depth (mm) | B7: 800 | D7: Surcharge (kPa) | E7: 10
A8: Loading | B8: Vehicular (LM1) | D8: GWT behind wall? (Y/N) | E8: N
A10: Selected width (mm) | B10: =_xlfn.MINIFS(Drain_Register!$D$5:$D$304,Drain_Register!$C$5:$C$304,B5,Drain_Register!$H$5:$H$304,B8,Drain_Register!$S$5:$S$304,"Approved",Drain_Register!$D$5:$D$304,">="&B6,Drain_Register!$E$5:$E$304,">="&B7) -> 600 | D10: Selected height (m) | E10: =_xlfn.MINIFS(RW_Register!$D$5:$D$304,RW_Register!$C$5:$C$304,E5,RW_Register!$Y$5:$Y$304,"Approved",RW_Register!$D$5:$D$304,">="&E6,RW_Register!$E$5:$E$304,">="&E7,RW_Register!$F$5:$F$304,IF(E8="Y","Y","<>#")) -> 3
A11: Selected depth (mm) | B11: =IF(B10=0,0,_xlfn.MINIFS(Drain_Register!$E$5:$E$304,Drain_Register!$C$5:$C$304,B5,Drain_Register!$H$5:$H$304,B8,Drain_Register!$S$5:$S$304,"Approved",Drain_Register!$D$5:$D$304,B10,Drain_Register!$E$5:$E$304,">="&B7)) -> 900 | D11: Selected surcharge (kPa) | E11: =IF(E10=0,0,_xlfn.MINIFS(RW_Register!$E$5:$E$304,RW_Register!$C$5:$C$304,E5,RW_Register!$Y$5:$Y$304,"Approved",RW_Register!$D$5:$D$304,E10,RW_Register!$E$5:$E$304,">="&E7,RW_Register!$F$5:$F$304,IF(E8="Y","Y","<>#"))) -> 10
A12: Row in register | B12: =IFERROR(MATCH(B5&"|"&B10&"|"&B11&"|"&B8&"|Approved",Drain_Register!$AH$5:$AH$304,0),0) -> 3 | D12: Selected GWT case | E12: =IF(E10=0,"",IF(E8="Y","Y",IF(COUNTIFS(RW_Register!$C$5:$C$304,E5,RW_Register!$Y$5:$Y$304,"Approved",RW_Register!$D$5:$D$304,E10,RW_Register!$E$5:$E$304,E11,RW_Register!$F$5:$F$304,"N")>0,"N","Y"))) -> N
D13: Row in register | E13: =IFERROR(MATCH(E5&"|"&E10&"|"&E11&"|"&E12&"|Approved",RW_Register!$AN$5:$AN$304,0),0) -> 5
A14: Result | B14: =IF(B12=0,"NO STANDARD DESIGN - bespoke design needed",IF(OR(B10>B6,B11>B7),"Match (conservative: larger than required)","Exact match")) -> Match (conservative: larger than required) | D14: Result | E14: =IF(E13=0,"NO STANDARD DESIGN - bespoke design needed",IF(OR(E10>E6,E11>E7,E12<>E8),"Match (conservative: covers a worse case)","Exact match")) -> Match (conservative: covers a worse case)
A15: Design ID | B15: =IF($B$12=0,"",INDEX(Drain_Register!$A$5:$A$304,$B$12)) -> DRN-UD-0600x0900-VEH-B | D15: Design ID | E15: =IF($E$13=0,"",INDEX(RW_Register!$A$5:$A$304,$E$13)) -> RW-CANT-H3000-S10-A
A16: Description | B16: =IF($B$12=0,"",INDEX(Drain_Register!$B$5:$B$304,$B$12)) -> U-Drain 600W x 900D, Vehicular (LM1), Cast-in-situ | D16: Description | E16: =IF($E$13=0,"",INDEX(RW_Register!$B$5:$B$304,$E$13)) -> Cantilever RC, H = 3.0 m, q = 10 kPa
A17: Rev | B17: =IF($B$12=0,"",INDEX(Drain_Register!$R$5:$R$304,$B$12)) -> B | D17: Rev | E17: =IF($E$13=0,"",INDEX(RW_Register!$X$5:$X$304,$E$13)) -> A
A18: Drawing No. | B18: =IF($B$12=0,"",INDEX(Drain_Register!$T$5:$T$304,$B$12)) -> STD-DRN-003 | D18: Drawing No. | E18: =IF($E$13=0,"",INDEX(RW_Register!$Z$5:$Z$304,$E$13)) -> STD-RW-005
A19: Wall / Base / Dist. bars | B19: =IF($B$12=0,"",INDEX(Drain_Register!$M$5:$M$304,$B$12)&" / "&INDEX(Drain_Register!$N$5:$N$304,$B$12)&" / "&INDEX(Drain_Register!$O$5:$O$304,$B$12)) -> T13@150 / T13@150 / T10@200 | D19: Stem / Base bars | E19: =IF($E$13=0,"",INDEX(RW_Register!$R$5:$R$304,$E$13)&" / "&INDEX(RW_Register!$S$5:$S$304,$E$13)) -> T16@125 / T16@150
A20: Tender Detail DWG | B20: =IF($B$12=0,"",INDEX(Drain_Register!$U$5:$U$304,$B$12)) -> Drainage/DRN-UD-0600x0900-VEH-B.dwg | D20: Tender Detail DWG | E20: =IF($E$13=0,"",INDEX(RW_Register!$AA$5:$AA$304,$E$13)) -> RetainingWall/RW-CANT-H3000-S10-A.dwg
A21: PDF | B21: =IF($B$12=0,"",INDEX(Drain_Register!$V$5:$V$304,$B$12)) -> Drainage/DRN-UD-0600x0900-VEH-B.pdf | D21: PDF | E21: =IF($E$13=0,"",INDEX(RW_Register!$AB$5:$AB$304,$E$13)) -> RetainingWall/RW-CANT-H3000-S10-A.pdf
A22: Calc Report | B22: =IF($B$12=0,"",INDEX(Drain_Register!$W$5:$W$304,$B$12)) -> Drainage/Calcs/DRN-UD-0600x0900-VEH-B_calc.pdf | D22: Calc Report | E22: =IF($E$13=0,"",INDEX(RW_Register!$AC$5:$AC$304,$E$13)) -> RetainingWall/Calcs/RW-CANT-H3000-S10-A_calc.pdf
A23: Concrete (m3/m) | B23: =IF($B$12=0,"",INDEX(Drain_Register!$X$5:$X$304,$B$12)) -> 0.405 | D23: Concrete (m3/m) | E23: =IF($E$13=0,"",INDEX(RW_Register!$AD$5:$AD$304,$E$13)) -> 2.08
A24: Rebar (kg/m) | B24: =IF($B$12=0,"",INDEX(Drain_Register!$Y$5:$Y$304,$B$12)) -> 48 | D24: Rebar (kg/m) | E24: =IF($E$13=0,"",INDEX(RW_Register!$AE$5:$AE$304,$E$13)) -> 160
A25: Limitations | B25: =IF($B$12=0,"",INDEX(Drain_Register!$AB$5:$AB$304,$B$12)) -> EXAMPLE values. Rev A superseded (cover increased). | D25: Limitations | E25: =IF($E$13=0,"",INDEX(RW_Register!$AH$5:$AH$304,$E$13)) -> EXAMPLE values.
A27: Note: loading is matched exactly (a Vehicular design is not offered for a Pedestrian search). A wall designed with GWT is offered for a no-GWT search, not the other way round.
A28: Copy the Design ID into the Tender_Pack sheet to add it to your tender.

Sheet Tender_Pack
A1: Tender Pack: designs used in this tender + preliminary quantities
A2: Type Design IDs (from any register) and the length / number. Everything else fills in. Save a copy of this workbook per tender, or copy this sheet out.
A3: Tender / Project: | B3: EXAMPLE - Tender T-2026-01 Road Upgrading
A5: Item | B5: Design ID | C5: Location / Remarks | D5: Length / Qty | E5: Unit | F5: Register | G5: Description | H5: Rev | I5: Status | J5: Drawing No. | K5: Tender Detail DWG | L5: Concrete (m3) | M5: Rebar / Steel (t) | N5: Formwork (m2) | O5: Excavation (m3) | P5: Check
A6: 1 | B6: DRN-UD-0600x0900-VEH-B | C6: Main road side drain, Ch 0-120 | D6: 120 | E6: =IF($B6="","",IF(F6="Others",IFERROR(INDEX(Other_Register!$S$5:$S$304,MATCH($B6,Other_Register!$A$5:$A$304,0)),""),IF(F6="", "","m"))) -> m | F6: =IF($B6="","",IF(ISNUMBER(MATCH($B6,Drain_Register!$A$5:$A$304,0)),"Drain",IF(ISNUMBER(MATCH($B6,RW_Register!$A$5:$A$304,0)),"Ret. Wall",IF(ISNUMBER(MATCH($B6,Other_Register!$A$5:$A$304,0)),"Others","")))) -> Drain | G6: =IF($B6="","",IFERROR(INDEX(Drain_Register!$B$5:$B$304,MATCH($B6,Drain_Register!$A$5:$A$304,0)),IFERROR(INDEX(RW_Register!$B$5:$B$304,MATCH($B6,RW_Register!$A$5:$A$304,0)),IFERROR(INDEX(Other_Register!$B$5:$B$304,MATCH($B6,Other_Register!$A$5:$A$304,0)),"ID not found - check spelling")))) -> U-Drain 600W x 900D, Vehicular (LM1), Cast-in-situ | H6: =IF($B6="","",IFERROR(INDEX(Drain_Register!$R$5:$R$304,MATCH($B6,Drain_Register!$A$5:$A$304,0)),IFERROR(INDEX(RW_Register!$X$5:$X$304,MATCH($B6,RW_Register!$A$5:$A$304,0)),IFERROR(INDEX(Other_Register!$M$5:$M$304,MATCH($B6,Other_Register!$A$5:$A$304,0)),"")))) -> B | I6: =IF($B6="","",IFERROR(INDEX(Drain_Register!$S$5:$S$304,MATCH($B6,Drain_Register!$A$5:$A$304,0)),IFERROR(INDEX(RW_Register!$Y$5:$Y$304,MATCH($B6,RW_Register!$A$5:$A$304,0)),IFERROR(INDEX(Other_Register!$N$5:$N$304,MATCH($B6,Other_Register!$A$5:$A$304,0)),"")))) -> Approved | J6: =IF($B6="","",IFERROR(INDEX(Drain_Register!$T$5:$T$304,MATCH($B6,Drain_Register!$A$5:$A$304,0)),IFERROR(INDEX(RW_Register!$Z$5:$Z$304,MATCH($B6,RW_Register!$A$5:$A$304,0)),IFERROR(INDEX(Other_Register!$O$5:$O$304,MATCH($B6,Other_Register!$A$5:$A$304,0)),"")))) -> STD-DRN-003 | K6: =IF($B6="","",IFERROR(INDEX(Drain_Register!$U$5:$U$304,MATCH($B6,Drain_Register!$A$5:$A$304,0)),IFERROR(INDEX(RW_Register!$AA$5:$AA$304,MATCH($B6,RW_Register!$A$5:$A$304,0)),IFERROR(INDEX(Other_Register!$P$5:$P$304,MATCH($B6,Other_Register!$A$5:$A$304,0)),"")))) -> Drainage/DRN-UD-0600x0900-VEH-B.dwg | L6: =IF(OR($B6="",$D6=""),"",$D6*IFERROR(INDEX(Drain_Register!$X$5:$X$304,MATCH($B6,Drain_Register!$A$5:$A$304,0)),IFERROR(INDEX(RW_Register!$AD$5:$AD$304,MATCH($B6,RW_Register!$A$5:$A$304,0)),IFERROR(INDEX(Other_Register!$T$5:$T$304,MATCH($B6,Other_Register!$A$5:$A$304,0)),0)))) -> 48.6 | M6: =IF(OR($B6="",$D6=""),"",$D6*IFERROR(INDEX(Drain_Register!$Y$5:$Y$304,MATCH($B6,Drain_Register!$A$5:$A$304,0)),IFERROR(INDEX(RW_Register!$AE$5:$AE$304,MATCH($B6,RW_Register!$A$5:$A$304,0)),IFERROR(INDEX(Other_Register!$U$5:$U$304,MATCH($B6,Other_Register!$A$5:$A$304,0)),0)))/1000) -> 5.76 | N6: =IF(OR($B6="",$D6=""),"",$D6*IFERROR(INDEX(Drain_Register!$Z$5:$Z$304,MATCH($B6,Drain_Register!$A$5:$A$304,0)),IFERROR(INDEX(RW_Register!$AF$5:$AF$304,MATCH($B6,RW_Register!$A$5:$A$304,0)),IFERROR(INDEX(Other_Register!$V$5:$V$304,MATCH($B6,Other_Register!$A$5:$A$304,0)),0)))) -> 450 | O6: =IF(OR($B6="",$D6=""),"",$D6*IFERROR(INDEX(Drain_Register!$AA$5:$AA$304,MATCH($B6,Drain_Register!$A$5:$A$304,0)),IFERROR(INDEX(RW_Register!$AG$5:$AG$304,MATCH($B6,RW_Register!$A$5:$A$304,0)),IFERROR(INDEX(Other_Register!$W$5:$W$304,MATCH($B6,Other_Register!$A$5:$A$304,0)),0)))) -> 252 | P6: =IF($B6="","",IF(F6="","ID not found",IF(I6<>"Approved","WARNING: status is "&I6,IF(D6="","Enter length / qty","OK")))) -> OK
A7: 2 | B7: DRN-UD-0300x0450-PED-A | C7: Footpath drain | D7: 85 | E7: =IF($B7="","",IF(F7="Others",IFERROR(INDEX(Other_Register!$S$5:$S$304,MATCH($B7,Other_Register!$A$5:$A$304,0)),""),IF(F7="", "","m"))) -> m | F7: =IF($B7="","",IF(ISNUMBER(MATCH($B7,Drain_Register!$A$5:$A$304,0)),"Drain",IF(ISNUMBER(MATCH($B7,RW_Register!$A$5:$A$304,0)),"Ret. Wall",IF(ISNUMBER(MATCH($B7,Other_Register!$A$5:$A$304,0)),"Others","")))) -> Drain | G7: =IF($B7="","",IFERROR(INDEX(Drain_Register!$B$5:$B$304,MATCH($B7,Drain_Register!$A$5:$A$304,0)),IFERROR(INDEX(RW_Register!$B$5:$B$304,MATCH($B7,RW_Register!$A$5:$A$304,0)),IFERROR(INDEX(Other_Register!$B$5:$B$304,MATCH($B7,Other_Register!$A$5:$A$304,0)),"ID not found - check spelling")))) -> U-Drain 300W x 450D, Pedestrian, Cast-in-situ | H7: =IF($B7="","",IFERROR(INDEX(Drain_Register!$R$5:$R$304,MATCH($B7,Drain_Register!$A$5:$A$304,0)),IFERROR(INDEX(RW_Register!$X$5:$X$304,MATCH($B7,RW_Register!$A$5:$A$304,0)),IFERROR(INDEX(Other_Register!$M$5:$M$304,MATCH($B7,Other_Register!$A$5:$A$304,0)),"")))) -> A | I7: =IF($B7="","",IFERROR(INDEX(Drain_Register!$S$5:$S$304,MATCH($B7,Drain_Register!$A$5:$A$304,0)),IFERROR(INDEX(RW_Register!$Y$5:$Y$304,MATCH($B7,RW_Register!$A$5:$A$304,0)),IFERROR(INDEX(Other_Register!$N$5:$N$304,MATCH($B7,Other_Register!$A$5:$A$304,0)),"")))) -> Approved | J7: =IF($B7="","",IFERROR(INDEX(Drain_Register!$T$5:$T$304,MATCH($B7,Drain_Register!$A$5:$A$304,0)),IFERROR(INDEX(RW_Register!$Z$5:$Z$304,MATCH($B7,RW_Register!$A$5:$A$304,0)),IFERROR(INDEX(Other_Register!$O$5:$O$304,MATCH($B7,Other_Register!$A$5:$A$304,0)),"")))) -> STD-DRN-001 | K7: =IF($B7="","",IFERROR(INDEX(Drain_Register!$U$5:$U$304,MATCH($B7,Drain_Register!$A$5:$A$304,0)),IFERROR(INDEX(RW_Register!$AA$5:$AA$304,MATCH($B7,RW_Register!$A$5:$A$304,0)),IFERROR(INDEX(Other_Register!$P$5:$P$304,MATCH($B7,Other_Register!$A$5:$A$304,0)),"")))) -> Drainage/DRN-UD-0300x0450-PED-A.dwg | L7: =IF(OR($B7="",$D7=""),"",$D7*IFERROR(INDEX(Drain_Register!$X$5:$X$304,MATCH($B7,Drain_Register!$A$5:$A$304,0)),IFERROR(INDEX(RW_Register!$AD$5:$AD$304,MATCH($B7,RW_Register!$A$5:$A$304,0)),IFERROR(INDEX(Other_Register!$T$5:$T$304,MATCH($B7,Other_Register!$A$5:$A$304,0)),0)))) -> 17 | M7: =IF(OR($B7="",$D7=""),"",$D7*IFERROR(INDEX(Drain_Register!$Y$5:$Y$304,MATCH($B7,Drain_Register!$A$5:$A$304,0)),IFERROR(INDEX(RW_Register!$AE$5:$AE$304,MATCH($B7,RW_Register!$A$5:$A$304,0)),IFERROR(INDEX(Other_Register!$U$5:$U$304,MATCH($B7,Other_Register!$A$5:$A$304,0)),0)))/1000) -> 1.53 | N7: =IF(OR($B7="",$D7=""),"",$D7*IFERROR(INDEX(Drain_Register!$Z$5:$Z$304,MATCH($B7,Drain_Register!$A$5:$A$304,0)),IFERROR(INDEX(RW_Register!$AF$5:$AF$304,MATCH($B7,RW_Register!$A$5:$A$304,0)),IFERROR(INDEX(Other_Register!$V$5:$V$304,MATCH($B7,Other_Register!$A$5:$A$304,0)),0)))) -> 187 | O7: =IF(OR($B7="",$D7=""),"",$D7*IFERROR(INDEX(Drain_Register!$AA$5:$AA$304,MATCH($B7,Drain_Register!$A$5:$A$304,0)),IFERROR(INDEX(RW_Register!$AG$5:$AG$304,MATCH($B7,RW_Register!$A$5:$A$304,0)),IFERROR(INDEX(Other_Register!$W$5:$W$304,MATCH($B7,Other_Register!$A$5:$A$304,0)),0)))) -> 80.75 | P7: =IF($B7="","",IF(F7="","ID not found",IF(I7<>"Approved","WARNING: status is "&I7,IF(D7="","Enter length / qty","OK")))) -> OK
A8: 3 | B8: RW-CANT-H3000-S10-A | C8: Slope at carpark, grid A-D | D8: 42 | E8: =IF($B8="","",IF(F8="Others",IFERROR(INDEX(Other_Register!$S$5:$S$304,MATCH($B8,Other_Register!$A$5:$A$304,0)),""),IF(F8="", "","m"))) -> m | F8: =IF($B8="","",IF(ISNUMBER(MATCH($B8,Drain_Register!$A$5:$A$304,0)),"Drain",IF(ISNUMBER(MATCH($B8,RW_Register!$A$5:$A$304,0)),"Ret. Wall",IF(ISNUMBER(MATCH($B8,Other_Register!$A$5:$A$304,0)),"Others","")))) -> Ret. Wall | G8: =IF($B8="","",IFERROR(INDEX(Drain_Register!$B$5:$B$304,MATCH($B8,Drain_Register!$A$5:$A$304,0)),IFERROR(INDEX(RW_Register!$B$5:$B$304,MATCH($B8,RW_Register!$A$5:$A$304,0)),IFERROR(INDEX(Other_Register!$B$5:$B$304,MATCH($B8,Other_Register!$A$5:$A$304,0)),"ID not found - check spelling")))) -> Cantilever RC, H = 3.0 m, q = 10 kPa | H8: =IF($B8="","",IFERROR(INDEX(Drain_Register!$R$5:$R$304,MATCH($B8,Drain_Register!$A$5:$A$304,0)),IFERROR(INDEX(RW_Register!$X$5:$X$304,MATCH($B8,RW_Register!$A$5:$A$304,0)),IFERROR(INDEX(Other_Register!$M$5:$M$304,MATCH($B8,Other_Register!$A$5:$A$304,0)),"")))) -> A | I8: =IF($B8="","",IFERROR(INDEX(Drain_Register!$S$5:$S$304,MATCH($B8,Drain_Register!$A$5:$A$304,0)),IFERROR(INDEX(RW_Register!$Y$5:$Y$304,MATCH($B8,RW_Register!$A$5:$A$304,0)),IFERROR(INDEX(Other_Register!$N$5:$N$304,MATCH($B8,Other_Register!$A$5:$A$304,0)),"")))) -> Approved | J8: =IF($B8="","",IFERROR(INDEX(Drain_Register!$T$5:$T$304,MATCH($B8,Drain_Register!$A$5:$A$304,0)),IFERROR(INDEX(RW_Register!$Z$5:$Z$304,MATCH($B8,RW_Register!$A$5:$A$304,0)),IFERROR(INDEX(Other_Register!$O$5:$O$304,MATCH($B8,Other_Register!$A$5:$A$304,0)),"")))) -> STD-RW-005 | K8: =IF($B8="","",IFERROR(INDEX(Drain_Register!$U$5:$U$304,MATCH($B8,Drain_Register!$A$5:$A$304,0)),IFERROR(INDEX(RW_Register!$AA$5:$AA$304,MATCH($B8,RW_Register!$A$5:$A$304,0)),IFERROR(INDEX(Other_Register!$P$5:$P$304,MATCH($B8,Other_Register!$A$5:$A$304,0)),"")))) -> RetainingWall/RW-CANT-H3000-S10-A.dwg | L8: =IF(OR($B8="",$D8=""),"",$D8*IFERROR(INDEX(Drain_Register!$X$5:$X$304,MATCH($B8,Drain_Register!$A$5:$A$304,0)),IFERROR(INDEX(RW_Register!$AD$5:$AD$304,MATCH($B8,RW_Register!$A$5:$A$304,0)),IFERROR(INDEX(Other_Register!$T$5:$T$304,MATCH($B8,Other_Register!$A$5:$A$304,0)),0)))) -> 87.36 | M8: =IF(OR($B8="",$D8=""),"",$D8*IFERROR(INDEX(Drain_Register!$Y$5:$Y$304,MATCH($B8,Drain_Register!$A$5:$A$304,0)),IFERROR(INDEX(RW_Register!$AE$5:$AE$304,MATCH($B8,RW_Register!$A$5:$A$304,0)),IFERROR(INDEX(Other_Register!$U$5:$U$304,MATCH($B8,Other_Register!$A$5:$A$304,0)),0)))/1000) -> 6.72 | N8: =IF(OR($B8="",$D8=""),"",$D8*IFERROR(INDEX(Drain_Register!$Z$5:$Z$304,MATCH($B8,Drain_Register!$A$5:$A$304,0)),IFERROR(INDEX(RW_Register!$AF$5:$AF$304,MATCH($B8,RW_Register!$A$5:$A$304,0)),IFERROR(INDEX(Other_Register!$V$5:$V$304,MATCH($B8,Other_Register!$A$5:$A$304,0)),0)))) -> 289.8 | O8: =IF(OR($B8="",$D8=""),"",$D8*IFERROR(INDEX(Drain_Register!$AA$5:$AA$304,MATCH($B8,Drain_Register!$A$5:$A$304,0)),IFERROR(INDEX(RW_Register!$AG$5:$AG$304,MATCH($B8,RW_Register!$A$5:$A$304,0)),IFERROR(INDEX(Other_Register!$W$5:$W$304,MATCH($B8,Other_Register!$A$5:$A$304,0)),0)))) -> 226.8 | P8: =IF($B8="","",IF(F8="","ID not found",IF(I8<>"Approved","WARNING: status is "&I8,IF(D8="","Enter length / qty","OK")))) -> OK
A9: 4 | B9: LKW-SINGLESPAN-SP6000-H3000-A | C9: Linkway to bus stop | D9: 8 | E9: =IF($B9="","",IF(F9="Others",IFERROR(INDEX(Other_Register!$S$5:$S$304,MATCH($B9,Other_Register!$A$5:$A$304,0)),""),IF(F9="", "","m"))) -> span | F9: =IF($B9="","",IF(ISNUMBER(MATCH($B9,Drain_Register!$A$5:$A$304,0)),"Drain",IF(ISNUMBER(MATCH($B9,RW_Register!$A$5:$A$304,0)),"Ret. Wall",IF(ISNUMBER(MATCH($B9,Other_Register!$A$5:$A$304,0)),"Others","")))) -> Others | G9: =IF($B9="","",IFERROR(INDEX(Drain_Register!$B$5:$B$304,MATCH($B9,Drain_Register!$A$5:$A$304,0)),IFERROR(INDEX(RW_Register!$B$5:$B$304,MATCH($B9,RW_Register!$A$5:$A$304,0)),IFERROR(INDEX(Other_Register!$B$5:$B$304,MATCH($B9,Other_Register!$A$5:$A$304,0)),"ID not found - check spelling")))) -> LTA Linkway - Single Span, span 6 m, H 3 m, W 2.4 m | H9: =IF($B9="","",IFERROR(INDEX(Drain_Register!$R$5:$R$304,MATCH($B9,Drain_Register!$A$5:$A$304,0)),IFERROR(INDEX(RW_Register!$X$5:$X$304,MATCH($B9,RW_Register!$A$5:$A$304,0)),IFERROR(INDEX(Other_Register!$M$5:$M$304,MATCH($B9,Other_Register!$A$5:$A$304,0)),"")))) -> A | I9: =IF($B9="","",IFERROR(INDEX(Drain_Register!$S$5:$S$304,MATCH($B9,Drain_Register!$A$5:$A$304,0)),IFERROR(INDEX(RW_Register!$Y$5:$Y$304,MATCH($B9,RW_Register!$A$5:$A$304,0)),IFERROR(INDEX(Other_Register!$N$5:$N$304,MATCH($B9,Other_Register!$A$5:$A$304,0)),"")))) -> Approved | J9: =IF($B9="","",IFERROR(INDEX(Drain_Register!$T$5:$T$304,MATCH($B9,Drain_Register!$A$5:$A$304,0)),IFERROR(INDEX(RW_Register!$Z$5:$Z$304,MATCH($B9,RW_Register!$A$5:$A$304,0)),IFERROR(INDEX(Other_Register!$O$5:$O$304,MATCH($B9,Other_Register!$A$5:$A$304,0)),"")))) -> STD-LKW-001 | K9: =IF($B9="","",IFERROR(INDEX(Drain_Register!$U$5:$U$304,MATCH($B9,Drain_Register!$A$5:$A$304,0)),IFERROR(INDEX(RW_Register!$AA$5:$AA$304,MATCH($B9,RW_Register!$A$5:$A$304,0)),IFERROR(INDEX(Other_Register!$P$5:$P$304,MATCH($B9,Other_Register!$A$5:$A$304,0)),"")))) -> Others/LKW-SINGLESPAN-SP6000-H3000-A.dwg | L9: =IF(OR($B9="",$D9=""),"",$D9*IFERROR(INDEX(Drain_Register!$X$5:$X$304,MATCH($B9,Drain_Register!$A$5:$A$304,0)),IFERROR(INDEX(RW_Register!$AD$5:$AD$304,MATCH($B9,RW_Register!$A$5:$A$304,0)),IFERROR(INDEX(Other_Register!$T$5:$T$304,MATCH($B9,Other_Register!$A$5:$A$304,0)),0)))) -> 9.6 | M9: =IF(OR($B9="",$D9=""),"",$D9*IFERROR(INDEX(Drain_Register!$Y$5:$Y$304,MATCH($B9,Drain_Register!$A$5:$A$304,0)),IFERROR(INDEX(RW_Register!$AE$5:$AE$304,MATCH($B9,RW_Register!$A$5:$A$304,0)),IFERROR(INDEX(Other_Register!$U$5:$U$304,MATCH($B9,Other_Register!$A$5:$A$304,0)),0)))/1000) -> 7.6 | N9: =IF(OR($B9="",$D9=""),"",$D9*IFERROR(INDEX(Drain_Register!$Z$5:$Z$304,MATCH($B9,Drain_Register!$A$5:$A$304,0)),IFERROR(INDEX(RW_Register!$AF$5:$AF$304,MATCH($B9,RW_Register!$A$5:$A$304,0)),IFERROR(INDEX(Other_Register!$V$5:$V$304,MATCH($B9,Other_Register!$A$5:$A$304,0)),0)))) -> 38.4 | O9: =IF(OR($B9="",$D9=""),"",$D9*IFERROR(INDEX(Drain_Register!$AA$5:$AA$304,MATCH($B9,Drain_Register!$A$5:$A$304,0)),IFERROR(INDEX(RW_Register!$AG$5:$AG$304,MATCH($B9,RW_Register!$A$5:$A$304,0)),IFERROR(INDEX(Other_Register!$W$5:$W$304,MATCH($B9,Other_Register!$A$5:$A$304,0)),0)))) -> 20 | P9: =IF($B9="","",IF(F9="","ID not found",IF(I9<>"Approved","WARNING: status is "&I9,IF(D9="","Enter length / qty","OK")))) -> OK
A10: 5 | B10: DRN-UD-1200x1500-HVY-A | C10: Fire engine access crossing | D10: 12 | E10: =IF($B10="","",IF(F10="Others",IFERROR(INDEX(Other_Register!$S$5:$S$304,MATCH($B10,Other_Register!$A$5:$A$304,0)),""),IF(F10="", "","m"))) -> m | F10: =IF($B10="","",IF(ISNUMBER(MATCH($B10,Drain_Register!$A$5:$A$304,0)),"Drain",IF(ISNUMBER(MATCH($B10,RW_Register!$A$5:$A$304,0)),"Ret. Wall",IF(ISNUMBER(MATCH($B10,Other_Register!$A$5:$A$304,0)),"Others","")))) -> Drain | G10: =IF($B10="","",IFERROR(INDEX(Drain_Register!$B$5:$B$304,MATCH($B10,Drain_Register!$A$5:$A$304,0)),IFERROR(INDEX(RW_Register!$B$5:$B$304,MATCH($B10,RW_Register!$A$5:$A$304,0)),IFERROR(INDEX(Other_Register!$B$5:$B$304,MATCH($B10,Other_Register!$A$5:$A$304,0)),"ID not found - check spelling")))) -> U-Drain 1200W x 1500D, Heavy Vehicle / Fire Engine, Cast-in-situ | H10: =IF($B10="","",IFERROR(INDEX(Drain_Register!$R$5:$R$304,MATCH($B10,Drain_Register!$A$5:$A$304,0)),IFERROR(INDEX(RW_Register!$X$5:$X$304,MATCH($B10,RW_Register!$A$5:$A$304,0)),IFERROR(INDEX(Other_Register!$M$5:$M$304,MATCH($B10,Other_Register!$A$5:$A$304,0)),"")))) -> A | I10: =IF($B10="","",IFERROR(INDEX(Drain_Register!$S$5:$S$304,MATCH($B10,Drain_Register!$A$5:$A$304,0)),IFERROR(INDEX(RW_Register!$Y$5:$Y$304,MATCH($B10,RW_Register!$A$5:$A$304,0)),IFERROR(INDEX(Other_Register!$N$5:$N$304,MATCH($B10,Other_Register!$A$5:$A$304,0)),"")))) -> Checked | J10: =IF($B10="","",IFERROR(INDEX(Drain_Register!$T$5:$T$304,MATCH($B10,Drain_Register!$A$5:$A$304,0)),IFERROR(INDEX(RW_Register!$Z$5:$Z$304,MATCH($B10,RW_Register!$A$5:$A$304,0)),IFERROR(INDEX(Other_Register!$O$5:$O$304,MATCH($B10,Other_Register!$A$5:$A$304,0)),"")))) -> STD-DRN-005 | K10: =IF($B10="","",IFERROR(INDEX(Drain_Register!$U$5:$U$304,MATCH($B10,Drain_Register!$A$5:$A$304,0)),IFERROR(INDEX(RW_Register!$AA$5:$AA$304,MATCH($B10,RW_Register!$A$5:$A$304,0)),IFERROR(INDEX(Other_Register!$P$5:$P$304,MATCH($B10,Other_Register!$A$5:$A$304,0)),"")))) -> Drainage/DRN-UD-1200x1500-HVY-A.dwg | L10: =IF(OR($B10="",$D10=""),"",$D10*IFERROR(INDEX(Drain_Register!$X$5:$X$304,MATCH($B10,Drain_Register!$A$5:$A$304,0)),IFERROR(INDEX(RW_Register!$AD$5:$AD$304,MATCH($B10,RW_Register!$A$5:$A$304,0)),IFERROR(INDEX(Other_Register!$T$5:$T$304,MATCH($B10,Other_Register!$A$5:$A$304,0)),0)))) -> 17.7 | M10: =IF(OR($B10="",$D10=""),"",$D10*IFERROR(INDEX(Drain_Register!$Y$5:$Y$304,MATCH($B10,Drain_Register!$A$5:$A$304,0)),IFERROR(INDEX(RW_Register!$AE$5:$AE$304,MATCH($B10,RW_Register!$A$5:$A$304,0)),IFERROR(INDEX(Other_Register!$U$5:$U$304,MATCH($B10,Other_Register!$A$5:$A$304,0)),0)))/1000) -> 1.98 | N10: =IF(OR($B10="",$D10=""),"",$D10*IFERROR(INDEX(Drain_Register!$Z$5:$Z$304,MATCH($B10,Drain_Register!$A$5:$A$304,0)),IFERROR(INDEX(RW_Register!$AF$5:$AF$304,MATCH($B10,RW_Register!$A$5:$A$304,0)),IFERROR(INDEX(Other_Register!$V$5:$V$304,MATCH($B10,Other_Register!$A$5:$A$304,0)),0)))) -> 78 | O10: =IF(OR($B10="",$D10=""),"",$D10*IFERROR(INDEX(Drain_Register!$AA$5:$AA$304,MATCH($B10,Drain_Register!$A$5:$A$304,0)),IFERROR(INDEX(RW_Register!$AG$5:$AG$304,MATCH($B10,RW_Register!$A$5:$A$304,0)),IFERROR(INDEX(Other_Register!$W$5:$W$304,MATCH($B10,Other_Register!$A$5:$A$304,0)),0)))) -> 61.2 | P10: =IF($B10="","",IF(F10="","ID not found",IF(I10<>"Approved","WARNING: status is "&I10,IF(D10="","Enter length / qty","OK")))) -> WARNING: status is Checked
E11: =IF($B11="","",IF(F11="Others",IFERROR(INDEX(Other_Register!$S$5:$S$304,MATCH($B11,Other_Register!$A$5:$A$304,0)),""),IF(F11="", "","m"))) | F11: =IF($B11="","",IF(ISNUMBER(MATCH($B11,Drain_Register!$A$5:$A$304,0)),"Drain",IF(ISNUMBER(MATCH($B11,RW_Register!$A$5:$A$304,0)),"Ret. Wall",IF(ISNUMBER(MATCH($B11,Other_Register!$A$5:$A$304,0)),"Others","")))) | G11: =IF($B11="","",IFERROR(INDEX(Drain_Register!$B$5:$B$304,MATCH($B11,Drain_Register!$A$5:$A$304,0)),IFERROR(INDEX(RW_Register!$B$5:$B$304,MATCH($B11,RW_Register!$A$5:$A$304,0)),IFERROR(INDEX(Other_Register!$B$5:$B$304,MATCH($B11,Other_Register!$A$5:$A$304,0)),"ID not found - check spelling")))) | H11: =IF($B11="","",IFERROR(INDEX(Drain_Register!$R$5:$R$304,MATCH($B11,Drain_Register!$A$5:$A$304,0)),IFERROR(INDEX(RW_Register!$X$5:$X$304,MATCH($B11,RW_Register!$A$5:$A$304,0)),IFERROR(INDEX(Other_Register!$M$5:$M$304,MATCH($B11,Other_Register!$A$5:$A$304,0)),"")))) | I11: =IF($B11="","",IFERROR(INDEX(Drain_Register!$S$5:$S$304,MATCH($B11,Drain_Register!$A$5:$A$304,0)),IFERROR(INDEX(RW_Register!$Y$5:$Y$304,MATCH($B11,RW_Register!$A$5:$A$304,0)),IFERROR(INDEX(Other_Register!$N$5:$N$304,MATCH($B11,Other_Register!$A$5:$A$304,0)),"")))) | J11: =IF($B11="","",IFERROR(INDEX(Drain_Register!$T$5:$T$304,MATCH($B11,Drain_Register!$A$5:$A$304,0)),IFERROR(INDEX(RW_Register!$Z$5:$Z$304,MATCH($B11,RW_Register!$A$5:$A$304,0)),IFERROR(INDEX(Other_Register!$O$5:$O$304,MATCH($B11,Other_Register!$A$5:$A$304,0)),"")))) | K11: =IF($B11="","",IFERROR(INDEX(Drain_Register!$U$5:$U$304,MATCH($B11,Drain_Register!$A$5:$A$304,0)),IFERROR(INDEX(RW_Register!$AA$5:$AA$304,MATCH($B11,RW_Register!$A$5:$A$304,0)),IFERROR(INDEX(Other_Register!$P$5:$P$304,MATCH($B11,Other_Register!$A$5:$A$304,0)),"")))) | L11: =IF(OR($B11="",$D11=""),"",$D11*IFERROR(INDEX(Drain_Register!$X$5:$X$304,MATCH($B11,Drain_Register!$A$5:$A$304,0)),IFERROR(INDEX(RW_Register!$AD$5:$AD$304,MATCH($B11,RW_Register!$A$5:$A$304,0)),IFERROR(INDEX(Other_Register!$T$5:$T$304,MATCH($B11,Other_Register!$A$5:$A$304,0)),0)))) | M11: =IF(OR($B11="",$D11=""),"",$D11*IFERROR(INDEX(Drain_Register!$Y$5:$Y$304,MATCH($B11,Drain_Register!$A$5:$A$304,0)),IFERROR(INDEX(RW_Register!$AE$5:$AE$304,MATCH($B11,RW_Register!$A$5:$A$304,0)),IFERROR(INDEX(Other_Register!$U$5:$U$304,MATCH($B11,Other_Register!$A$5:$A$304,0)),0)))/1000) | N11: =IF(OR($B11="",$D11=""),"",$D11*IFERROR(INDEX(Drain_Register!$Z$5:$Z$304,MATCH($B11,Drain_Register!$A$5:$A$304,0)),IFERROR(INDEX(RW_Register!$AF$5:$AF$304,MATCH($B11,RW_Register!$A$5:$A$304,0)),IFERROR(INDEX(Other_Register!$V$5:$V$304,MATCH($B11,Other_Register!$A$5:$A$304,0)),0)))) | O11: =IF(OR($B11="",$D11=""),"",$D11*IFERROR(INDEX(Drain_Register!$AA$5:$AA$304,MATCH($B11,Drain_Register!$A$5:$A$304,0)),IFERROR(INDEX(RW_Register!$AG$5:$AG$304,MATCH($B11,RW_Register!$A$5:$A$304,0)),IFERROR(INDEX(Other_Register!$W$5:$W$304,MATCH($B11,Other_Register!$A$5:$A$304,0)),0)))) | P11: =IF($B11="","",IF(F11="","ID not found",IF(I11<>"Approved","WARNING: status is "&I11,IF(D11="","Enter length / qty","OK"))))
E12: =IF($B12="","",IF(F12="Others",IFERROR(INDEX(Other_Register!$S$5:$S$304,MATCH($B12,Other_Register!$A$5:$A$304,0)),""),IF(F12="", "","m"))) | F12: =IF($B12="","",IF(ISNUMBER(MATCH($B12,Drain_Register!$A$5:$A$304,0)),"Drain",IF(ISNUMBER(MATCH($B12,RW_Register!$A$5:$A$304,0)),"Ret. Wall",IF(ISNUMBER(MATCH($B12,Other_Register!$A$5:$A$304,0)),"Others","")))) | G12: =IF($B12="","",IFERROR(INDEX(Drain_Register!$B$5:$B$304,MATCH($B12,Drain_Register!$A$5:$A$304,0)),IFERROR(INDEX(RW_Register!$B$5:$B$304,MATCH($B12,RW_Register!$A$5:$A$304,0)),IFERROR(INDEX(Other_Register!$B$5:$B$304,MATCH($B12,Other_Register!$A$5:$A$304,0)),"ID not found - check spelling")))) | H12: =IF($B12="","",IFERROR(INDEX(Drain_Register!$R$5:$R$304,MATCH($B12,Drain_Register!$A$5:$A$304,0)),IFERROR(INDEX(RW_Register!$X$5:$X$304,MATCH($B12,RW_Register!$A$5:$A$304,0)),IFERROR(INDEX(Other_Register!$M$5:$M$304,MATCH($B12,Other_Register!$A$5:$A$304,0)),"")))) | I12: =IF($B12="","",IFERROR(INDEX(Drain_Register!$S$5:$S$304,MATCH($B12,Drain_Register!$A$5:$A$304,0)),IFERROR(INDEX(RW_Register!$Y$5:$Y$304,MATCH($B12,RW_Register!$A$5:$A$304,0)),IFERROR(INDEX(Other_Register!$N$5:$N$304,MATCH($B12,Other_Register!$A$5:$A$304,0)),"")))) | J12: =IF($B12="","",IFERROR(INDEX(Drain_Register!$T$5:$T$304,MATCH($B12,Drain_Register!$A$5:$A$304,0)),IFERROR(INDEX(RW_Register!$Z$5:$Z$304,MATCH($B12,RW_Register!$A$5:$A$304,0)),IFERROR(INDEX(Other_Register!$O$5:$O$304,MATCH($B12,Other_Register!$A$5:$A$304,0)),"")))) | K12: =IF($B12="","",IFERROR(INDEX(Drain_Register!$U$5:$U$304,MATCH($B12,Drain_Register!$A$5:$A$304,0)),IFERROR(INDEX(RW_Register!$AA$5:$AA$304,MATCH($B12,RW_Register!$A$5:$A$304,0)),IFERROR(INDEX(Other_Register!$P$5:$P$304,MATCH($B12,Other_Register!$A$5:$A$304,0)),"")))) | L12: =IF(OR($B12="",$D12=""),"",$D12*IFERROR(INDEX(Drain_Register!$X$5:$X$304,MATCH($B12,Drain_Register!$A$5:$A$304,0)),IFERROR(INDEX(RW_Register!$AD$5:$AD$304,MATCH($B12,RW_Register!$A$5:$A$304,0)),IFERROR(INDEX(Other_Register!$T$5:$T$304,MATCH($B12,Other_Register!$A$5:$A$304,0)),0)))) | M12: =IF(OR($B12="",$D12=""),"",$D12*IFERROR(INDEX(Drain_Register!$Y$5:$Y$304,MATCH($B12,Drain_Register!$A$5:$A$304,0)),IFERROR(INDEX(RW_Register!$AE$5:$AE$304,MATCH($B12,RW_Register!$A$5:$A$304,0)),IFERROR(INDEX(Other_Register!$U$5:$U$304,MATCH($B12,Other_Register!$A$5:$A$304,0)),0)))/1000) | N12: =IF(OR($B12="",$D12=""),"",$D12*IFERROR(INDEX(Drain_Register!$Z$5:$Z$304,MATCH($B12,Drain_Register!$A$5:$A$304,0)),IFERROR(INDEX(RW_Register!$AF$5:$AF$304,MATCH($B12,RW_Register!$A$5:$A$304,0)),IFERROR(INDEX(Other_Register!$V$5:$V$304,MATCH($B12,Other_Register!$A$5:$A$304,0)),0)))) | O12: =IF(OR($B12="",$D12=""),"",$D12*IFERROR(INDEX(Drain_Register!$AA$5:$AA$304,MATCH($B12,Drain_Register!$A$5:$A$304,0)),IFERROR(INDEX(RW_Register!$AG$5:$AG$304,MATCH($B12,RW_Register!$A$5:$A$304,0)),IFERROR(INDEX(Other_Register!$W$5:$W$304,MATCH($B12,Other_Register!$A$5:$A$304,0)),0)))) | P12: =IF($B12="","",IF(F12="","ID not found",IF(I12<>"Approved","WARNING: status is "&I12,IF(D12="","Enter length / qty","OK"))))
E13: =IF($B13="","",IF(F13="Others",IFERROR(INDEX(Other_Register!$S$5:$S$304,MATCH($B13,Other_Register!$A$5:$A$304,0)),""),IF(F13="", "","m"))) | F13: =IF($B13="","",IF(ISNUMBER(MATCH($B13,Drain_Register!$A$5:$A$304,0)),"Drain",IF(ISNUMBER(MATCH($B13,RW_Register!$A$5:$A$304,0)),"Ret. Wall",IF(ISNUMBER(MATCH($B13,Other_Register!$A$5:$A$304,0)),"Others","")))) | G13: =IF($B13="","",IFERROR(INDEX(Drain_Register!$B$5:$B$304,MATCH($B13,Drain_Register!$A$5:$A$304,0)),IFERROR(INDEX(RW_Register!$B$5:$B$304,MATCH($B13,RW_Register!$A$5:$A$304,0)),IFERROR(INDEX(Other_Register!$B$5:$B$304,MATCH($B13,Other_Register!$A$5:$A$304,0)),"ID not found - check spelling")))) | H13: =IF($B13="","",IFERROR(INDEX(Drain_Register!$R$5:$R$304,MATCH($B13,Drain_Register!$A$5:$A$304,0)),IFERROR(INDEX(RW_Register!$X$5:$X$304,MATCH($B13,RW_Register!$A$5:$A$304,0)),IFERROR(INDEX(Other_Register!$M$5:$M$304,MATCH($B13,Other_Register!$A$5:$A$304,0)),"")))) | I13: =IF($B13="","",IFERROR(INDEX(Drain_Register!$S$5:$S$304,MATCH($B13,Drain_Register!$A$5:$A$304,0)),IFERROR(INDEX(RW_Register!$Y$5:$Y$304,MATCH($B13,RW_Register!$A$5:$A$304,0)),IFERROR(INDEX(Other_Register!$N$5:$N$304,MATCH($B13,Other_Register!$A$5:$A$304,0)),"")))) | J13: =IF($B13="","",IFERROR(INDEX(Drain_Register!$T$5:$T$304,MATCH($B13,Drain_Register!$A$5:$A$304,0)),IFERROR(INDEX(RW_Register!$Z$5:$Z$304,MATCH($B13,RW_Register!$A$5:$A$304,0)),IFERROR(INDEX(Other_Register!$O$5:$O$304,MATCH($B13,Other_Register!$A$5:$A$304,0)),"")))) | K13: =IF($B13="","",IFERROR(INDEX(Drain_Register!$U$5:$U$304,MATCH($B13,Drain_Register!$A$5:$A$304,0)),IFERROR(INDEX(RW_Register!$AA$5:$AA$304,MATCH($B13,RW_Register!$A$5:$A$304,0)),IFERROR(INDEX(Other_Register!$P$5:$P$304,MATCH($B13,Other_Register!$A$5:$A$304,0)),"")))) | L13: =IF(OR($B13="",$D13=""),"",$D13*IFERROR(INDEX(Drain_Register!$X$5:$X$304,MATCH($B13,Drain_Register!$A$5:$A$304,0)),IFERROR(INDEX(RW_Register!$AD$5:$AD$304,MATCH($B13,RW_Register!$A$5:$A$304,0)),IFERROR(INDEX(Other_Register!$T$5:$T$304,MATCH($B13,Other_Register!$A$5:$A$304,0)),0)))) | M13: =IF(OR($B13="",$D13=""),"",$D13*IFERROR(INDEX(Drain_Register!$Y$5:$Y$304,MATCH($B13,Drain_Register!$A$5:$A$304,0)),IFERROR(INDEX(RW_Register!$AE$5:$AE$304,MATCH($B13,RW_Register!$A$5:$A$304,0)),IFERROR(INDEX(Other_Register!$U$5:$U$304,MATCH($B13,Other_Register!$A$5:$A$304,0)),0)))/1000) | N13: =IF(OR($B13="",$D13=""),"",$D13*IFERROR(INDEX(Drain_Register!$Z$5:$Z$304,MATCH($B13,Drain_Register!$A$5:$A$304,0)),IFERROR(INDEX(RW_Register!$AF$5:$AF$304,MATCH($B13,RW_Register!$A$5:$A$304,0)),IFERROR(INDEX(Other_Register!$V$5:$V$304,MATCH($B13,Other_Register!$A$5:$A$304,0)),0)))) | O13: =IF(OR($B13="",$D13=""),"",$D13*IFERROR(INDEX(Drain_Register!$AA$5:$AA$304,MATCH($B13,Drain_Register!$A$5:$A$304,0)),IFERROR(INDEX(RW_Register!$AG$5:$AG$304,MATCH($B13,RW_Register!$A$5:$A$304,0)),IFERROR(INDEX(Other_Register!$W$5:$W$304,MATCH($B13,Other_Register!$A$5:$A$304,0)),0)))) | P13: =IF($B13="","",IF(F13="","ID not found",IF(I13<>"Approved","WARNING: status is "&I13,IF(D13="","Enter length / qty","OK"))))
E14: =IF($B14="","",IF(F14="Others",IFERROR(INDEX(Other_Register!$S$5:$S$304,MATCH($B14,Other_Register!$A$5:$A$304,0)),""),IF(F14="", "","m"))) | F14: =IF($B14="","",IF(ISNUMBER(MATCH($B14,Drain_Register!$A$5:$A$304,0)),"Drain",IF(ISNUMBER(MATCH($B14,RW_Register!$A$5:$A$304,0)),"Ret. Wall",IF(ISNUMBER(MATCH($B14,Other_Register!$A$5:$A$304,0)),"Others","")))) | G14: =IF($B14="","",IFERROR(INDEX(Drain_Register!$B$5:$B$304,MATCH($B14,Drain_Register!$A$5:$A$304,0)),IFERROR(INDEX(RW_Register!$B$5:$B$304,MATCH($B14,RW_Register!$A$5:$A$304,0)),IFERROR(INDEX(Other_Register!$B$5:$B$304,MATCH($B14,Other_Register!$A$5:$A$304,0)),"ID not found - check spelling")))) | H14: =IF($B14="","",IFERROR(INDEX(Drain_Register!$R$5:$R$304,MATCH($B14,Drain_Register!$A$5:$A$304,0)),IFERROR(INDEX(RW_Register!$X$5:$X$304,MATCH($B14,RW_Register!$A$5:$A$304,0)),IFERROR(INDEX(Other_Register!$M$5:$M$304,MATCH($B14,Other_Register!$A$5:$A$304,0)),"")))) | I14: =IF($B14="","",IFERROR(INDEX(Drain_Register!$S$5:$S$304,MATCH($B14,Drain_Register!$A$5:$A$304,0)),IFERROR(INDEX(RW_Register!$Y$5:$Y$304,MATCH($B14,RW_Register!$A$5:$A$304,0)),IFERROR(INDEX(Other_Register!$N$5:$N$304,MATCH($B14,Other_Register!$A$5:$A$304,0)),"")))) | J14: =IF($B14="","",IFERROR(INDEX(Drain_Register!$T$5:$T$304,MATCH($B14,Drain_Register!$A$5:$A$304,0)),IFERROR(INDEX(RW_Register!$Z$5:$Z$304,MATCH($B14,RW_Register!$A$5:$A$304,0)),IFERROR(INDEX(Other_Register!$O$5:$O$304,MATCH($B14,Other_Register!$A$5:$A$304,0)),"")))) | K14: =IF($B14="","",IFERROR(INDEX(Drain_Register!$U$5:$U$304,MATCH($B14,Drain_Register!$A$5:$A$304,0)),IFERROR(INDEX(RW_Register!$AA$5:$AA$304,MATCH($B14,RW_Register!$A$5:$A$304,0)),IFERROR(INDEX(Other_Register!$P$5:$P$304,MATCH($B14,Other_Register!$A$5:$A$304,0)),"")))) | L14: =IF(OR($B14="",$D14=""),"",$D14*IFERROR(INDEX(Drain_Register!$X$5:$X$304,MATCH($B14,Drain_Register!$A$5:$A$304,0)),IFERROR(INDEX(RW_Register!$AD$5:$AD$304,MATCH($B14,RW_Register!$A$5:$A$304,0)),IFERROR(INDEX(Other_Register!$T$5:$T$304,MATCH($B14,Other_Register!$A$5:$A$304,0)),0)))) | M14: =IF(OR($B14="",$D14=""),"",$D14*IFERROR(INDEX(Drain_Register!$Y$5:$Y$304,MATCH($B14,Drain_Register!$A$5:$A$304,0)),IFERROR(INDEX(RW_Register!$AE$5:$AE$304,MATCH($B14,RW_Register!$A$5:$A$304,0)),IFERROR(INDEX(Other_Register!$U$5:$U$304,MATCH($B14,Other_Register!$A$5:$A$304,0)),0)))/1000) | N14: =IF(OR($B14="",$D14=""),"",$D14*IFERROR(INDEX(Drain_Register!$Z$5:$Z$304,MATCH($B14,Drain_Register!$A$5:$A$304,0)),IFERROR(INDEX(RW_Register!$AF$5:$AF$304,MATCH($B14,RW_Register!$A$5:$A$304,0)),IFERROR(INDEX(Other_Register!$V$5:$V$304,MATCH($B14,Other_Register!$A$5:$A$304,0)),0)))) | O14: =IF(OR($B14="",$D14=""),"",$D14*IFERROR(INDEX(Drain_Register!$AA$5:$AA$304,MATCH($B14,Drain_Register!$A$5:$A$304,0)),IFERROR(INDEX(RW_Register!$AG$5:$AG$304,MATCH($B14,RW_Register!$A$5:$A$304,0)),IFERROR(INDEX(Other_Register!$W$5:$W$304,MATCH($B14,Other_Register!$A$5:$A$304,0)),0)))) | P14: =IF($B14="","",IF(F14="","ID not found",IF(I14<>"Approved","WARNING: status is "&I14,IF(D14="","Enter length / qty","OK"))))
E15: =IF($B15="","",IF(F15="Others",IFERROR(INDEX(Other_Register!$S$5:$S$304,MATCH($B15,Other_Register!$A$5:$A$304,0)),""),IF(F15="", "","m"))) | F15: =IF($B15="","",IF(ISNUMBER(MATCH($B15,Drain_Register!$A$5:$A$304,0)),"Drain",IF(ISNUMBER(MATCH($B15,RW_Register!$A$5:$A$304,0)),"Ret. Wall",IF(ISNUMBER(MATCH($B15,Other_Register!$A$5:$A$304,0)),"Others","")))) | G15: =IF($B15="","",IFERROR(INDEX(Drain_Register!$B$5:$B$304,MATCH($B15,Drain_Register!$A$5:$A$304,0)),IFERROR(INDEX(RW_Register!$B$5:$B$304,MATCH($B15,RW_Register!$A$5:$A$304,0)),IFERROR(INDEX(Other_Register!$B$5:$B$304,MATCH($B15,Other_Register!$A$5:$A$304,0)),"ID not found - check spelling")))) | H15: =IF($B15="","",IFERROR(INDEX(Drain_Register!$R$5:$R$304,MATCH($B15,Drain_Register!$A$5:$A$304,0)),IFERROR(INDEX(RW_Register!$X$5:$X$304,MATCH($B15,RW_Register!$A$5:$A$304,0)),IFERROR(INDEX(Other_Register!$M$5:$M$304,MATCH($B15,Other_Register!$A$5:$A$304,0)),"")))) | I15: =IF($B15="","",IFERROR(INDEX(Drain_Register!$S$5:$S$304,MATCH($B15,Drain_Register!$A$5:$A$304,0)),IFERROR(INDEX(RW_Register!$Y$5:$Y$304,MATCH($B15,RW_Register!$A$5:$A$304,0)),IFERROR(INDEX(Other_Register!$N$5:$N$304,MATCH($B15,Other_Register!$A$5:$A$304,0)),"")))) | J15: =IF($B15="","",IFERROR(INDEX(Drain_Register!$T$5:$T$304,MATCH($B15,Drain_Register!$A$5:$A$304,0)),IFERROR(INDEX(RW_Register!$Z$5:$Z$304,MATCH($B15,RW_Register!$A$5:$A$304,0)),IFERROR(INDEX(Other_Register!$O$5:$O$304,MATCH($B15,Other_Register!$A$5:$A$304,0)),"")))) | K15: =IF($B15="","",IFERROR(INDEX(Drain_Register!$U$5:$U$304,MATCH($B15,Drain_Register!$A$5:$A$304,0)),IFERROR(INDEX(RW_Register!$AA$5:$AA$304,MATCH($B15,RW_Register!$A$5:$A$304,0)),IFERROR(INDEX(Other_Register!$P$5:$P$304,MATCH($B15,Other_Register!$A$5:$A$304,0)),"")))) | L15: =IF(OR($B15="",$D15=""),"",$D15*IFERROR(INDEX(Drain_Register!$X$5:$X$304,MATCH($B15,Drain_Register!$A$5:$A$304,0)),IFERROR(INDEX(RW_Register!$AD$5:$AD$304,MATCH($B15,RW_Register!$A$5:$A$304,0)),IFERROR(INDEX(Other_Register!$T$5:$T$304,MATCH($B15,Other_Register!$A$5:$A$304,0)),0)))) | M15: =IF(OR($B15="",$D15=""),"",$D15*IFERROR(INDEX(Drain_Register!$Y$5:$Y$304,MATCH($B15,Drain_Register!$A$5:$A$304,0)),IFERROR(INDEX(RW_Register!$AE$5:$AE$304,MATCH($B15,RW_Register!$A$5:$A$304,0)),IFERROR(INDEX(Other_Register!$U$5:$U$304,MATCH($B15,Other_Register!$A$5:$A$304,0)),0)))/1000) | N15: =IF(OR($B15="",$D15=""),"",$D15*IFERROR(INDEX(Drain_Register!$Z$5:$Z$304,MATCH($B15,Drain_Register!$A$5:$A$304,0)),IFERROR(INDEX(RW_Register!$AF$5:$AF$304,MATCH($B15,RW_Register!$A$5:$A$304,0)),IFERROR(INDEX(Other_Register!$V$5:$V$304,MATCH($B15,Other_Register!$A$5:$A$304,0)),0)))) | O15: =IF(OR($B15="",$D15=""),"",$D15*IFERROR(INDEX(Drain_Register!$AA$5:$AA$304,MATCH($B15,Drain_Register!$A$5:$A$304,0)),IFERROR(INDEX(RW_Register!$AG$5:$AG$304,MATCH($B15,RW_Register!$A$5:$A$304,0)),IFERROR(INDEX(Other_Register!$W$5:$W$304,MATCH($B15,Other_Register!$A$5:$A$304,0)),0)))) | P15: =IF($B15="","",IF(F15="","ID not found",IF(I15<>"Approved","WARNING: status is "&I15,IF(D15="","Enter length / qty","OK"))))
E16: =IF($B16="","",IF(F16="Others",IFERROR(INDEX(Other_Register!$S$5:$S$304,MATCH($B16,Other_Register!$A$5:$A$304,0)),""),IF(F16="", "","m"))) | F16: =IF($B16="","",IF(ISNUMBER(MATCH($B16,Drain_Register!$A$5:$A$304,0)),"Drain",IF(ISNUMBER(MATCH($B16,RW_Register!$A$5:$A$304,0)),"Ret. Wall",IF(ISNUMBER(MATCH($B16,Other_Register!$A$5:$A$304,0)),"Others","")))) | G16: =IF($B16="","",IFERROR(INDEX(Drain_Register!$B$5:$B$304,MATCH($B16,Drain_Register!$A$5:$A$304,0)),IFERROR(INDEX(RW_Register!$B$5:$B$304,MATCH($B16,RW_Register!$A$5:$A$304,0)),IFERROR(INDEX(Other_Register!$B$5:$B$304,MATCH($B16,Other_Register!$A$5:$A$304,0)),"ID not found - check spelling")))) | H16: =IF($B16="","",IFERROR(INDEX(Drain_Register!$R$5:$R$304,MATCH($B16,Drain_Register!$A$5:$A$304,0)),IFERROR(INDEX(RW_Register!$X$5:$X$304,MATCH($B16,RW_Register!$A$5:$A$304,0)),IFERROR(INDEX(Other_Register!$M$5:$M$304,MATCH($B16,Other_Register!$A$5:$A$304,0)),"")))) | I16: =IF($B16="","",IFERROR(INDEX(Drain_Register!$S$5:$S$304,MATCH($B16,Drain_Register!$A$5:$A$304,0)),IFERROR(INDEX(RW_Register!$Y$5:$Y$304,MATCH($B16,RW_Register!$A$5:$A$304,0)),IFERROR(INDEX(Other_Register!$N$5:$N$304,MATCH($B16,Other_Register!$A$5:$A$304,0)),"")))) | J16: =IF($B16="","",IFERROR(INDEX(Drain_Register!$T$5:$T$304,MATCH($B16,Drain_Register!$A$5:$A$304,0)),IFERROR(INDEX(RW_Register!$Z$5:$Z$304,MATCH($B16,RW_Register!$A$5:$A$304,0)),IFERROR(INDEX(Other_Register!$O$5:$O$304,MATCH($B16,Other_Register!$A$5:$A$304,0)),"")))) | K16: =IF($B16="","",IFERROR(INDEX(Drain_Register!$U$5:$U$304,MATCH($B16,Drain_Register!$A$5:$A$304,0)),IFERROR(INDEX(RW_Register!$AA$5:$AA$304,MATCH($B16,RW_Register!$A$5:$A$304,0)),IFERROR(INDEX(Other_Register!$P$5:$P$304,MATCH($B16,Other_Register!$A$5:$A$304,0)),"")))) | L16: =IF(OR($B16="",$D16=""),"",$D16*IFERROR(INDEX(Drain_Register!$X$5:$X$304,MATCH($B16,Drain_Register!$A$5:$A$304,0)),IFERROR(INDEX(RW_Register!$AD$5:$AD$304,MATCH($B16,RW_Register!$A$5:$A$304,0)),IFERROR(INDEX(Other_Register!$T$5:$T$304,MATCH($B16,Other_Register!$A$5:$A$304,0)),0)))) | M16: =IF(OR($B16="",$D16=""),"",$D16*IFERROR(INDEX(Drain_Register!$Y$5:$Y$304,MATCH($B16,Drain_Register!$A$5:$A$304,0)),IFERROR(INDEX(RW_Register!$AE$5:$AE$304,MATCH($B16,RW_Register!$A$5:$A$304,0)),IFERROR(INDEX(Other_Register!$U$5:$U$304,MATCH($B16,Other_Register!$A$5:$A$304,0)),0)))/1000) | N16: =IF(OR($B16="",$D16=""),"",$D16*IFERROR(INDEX(Drain_Register!$Z$5:$Z$304,MATCH($B16,Drain_Register!$A$5:$A$304,0)),IFERROR(INDEX(RW_Register!$AF$5:$AF$304,MATCH($B16,RW_Register!$A$5:$A$304,0)),IFERROR(INDEX(Other_Register!$V$5:$V$304,MATCH($B16,Other_Register!$A$5:$A$304,0)),0)))) | O16: =IF(OR($B16="",$D16=""),"",$D16*IFERROR(INDEX(Drain_Register!$AA$5:$AA$304,MATCH($B16,Drain_Register!$A$5:$A$304,0)),IFERROR(INDEX(RW_Register!$AG$5:$AG$304,MATCH($B16,RW_Register!$A$5:$A$304,0)),IFERROR(INDEX(Other_Register!$W$5:$W$304,MATCH($B16,Other_Register!$A$5:$A$304,0)),0)))) | P16: =IF($B16="","",IF(F16="","ID not found",IF(I16<>"Approved","WARNING: status is "&I16,IF(D16="","Enter length / qty","OK"))))
E17: =IF($B17="","",IF(F17="Others",IFERROR(INDEX(Other_Register!$S$5:$S$304,MATCH($B17,Other_Register!$A$5:$A$304,0)),""),IF(F17="", "","m"))) | F17: =IF($B17="","",IF(ISNUMBER(MATCH($B17,Drain_Register!$A$5:$A$304,0)),"Drain",IF(ISNUMBER(MATCH($B17,RW_Register!$A$5:$A$304,0)),"Ret. Wall",IF(ISNUMBER(MATCH($B17,Other_Register!$A$5:$A$304,0)),"Others","")))) | G17: =IF($B17="","",IFERROR(INDEX(Drain_Register!$B$5:$B$304,MATCH($B17,Drain_Register!$A$5:$A$304,0)),IFERROR(INDEX(RW_Register!$B$5:$B$304,MATCH($B17,RW_Register!$A$5:$A$304,0)),IFERROR(INDEX(Other_Register!$B$5:$B$304,MATCH($B17,Other_Register!$A$5:$A$304,0)),"ID not found - check spelling")))) | H17: =IF($B17="","",IFERROR(INDEX(Drain_Register!$R$5:$R$304,MATCH($B17,Drain_Register!$A$5:$A$304,0)),IFERROR(INDEX(RW_Register!$X$5:$X$304,MATCH($B17,RW_Register!$A$5:$A$304,0)),IFERROR(INDEX(Other_Register!$M$5:$M$304,MATCH($B17,Other_Register!$A$5:$A$304,0)),"")))) | I17: =IF($B17="","",IFERROR(INDEX(Drain_Register!$S$5:$S$304,MATCH($B17,Drain_Register!$A$5:$A$304,0)),IFERROR(INDEX(RW_Register!$Y$5:$Y$304,MATCH($B17,RW_Register!$A$5:$A$304,0)),IFERROR(INDEX(Other_Register!$N$5:$N$304,MATCH($B17,Other_Register!$A$5:$A$304,0)),"")))) | J17: =IF($B17="","",IFERROR(INDEX(Drain_Register!$T$5:$T$304,MATCH($B17,Drain_Register!$A$5:$A$304,0)),IFERROR(INDEX(RW_Register!$Z$5:$Z$304,MATCH($B17,RW_Register!$A$5:$A$304,0)),IFERROR(INDEX(Other_Register!$O$5:$O$304,MATCH($B17,Other_Register!$A$5:$A$304,0)),"")))) | K17: =IF($B17="","",IFERROR(INDEX(Drain_Register!$U$5:$U$304,MATCH($B17,Drain_Register!$A$5:$A$304,0)),IFERROR(INDEX(RW_Register!$AA$5:$AA$304,MATCH($B17,RW_Register!$A$5:$A$304,0)),IFERROR(INDEX(Other_Register!$P$5:$P$304,MATCH($B17,Other_Register!$A$5:$A$304,0)),"")))) | L17: =IF(OR($B17="",$D17=""),"",$D17*IFERROR(INDEX(Drain_Register!$X$5:$X$304,MATCH($B17,Drain_Register!$A$5:$A$304,0)),IFERROR(INDEX(RW_Register!$AD$5:$AD$304,MATCH($B17,RW_Register!$A$5:$A$304,0)),IFERROR(INDEX(Other_Register!$T$5:$T$304,MATCH($B17,Other_Register!$A$5:$A$304,0)),0)))) | M17: =IF(OR($B17="",$D17=""),"",$D17*IFERROR(INDEX(Drain_Register!$Y$5:$Y$304,MATCH($B17,Drain_Register!$A$5:$A$304,0)),IFERROR(INDEX(RW_Register!$AE$5:$AE$304,MATCH($B17,RW_Register!$A$5:$A$304,0)),IFERROR(INDEX(Other_Register!$U$5:$U$304,MATCH($B17,Other_Register!$A$5:$A$304,0)),0)))/1000) | N17: =IF(OR($B17="",$D17=""),"",$D17*IFERROR(INDEX(Drain_Register!$Z$5:$Z$304,MATCH($B17,Drain_Register!$A$5:$A$304,0)),IFERROR(INDEX(RW_Register!$AF$5:$AF$304,MATCH($B17,RW_Register!$A$5:$A$304,0)),IFERROR(INDEX(Other_Register!$V$5:$V$304,MATCH($B17,Other_Register!$A$5:$A$304,0)),0)))) | O17: =IF(OR($B17="",$D17=""),"",$D17*IFERROR(INDEX(Drain_Register!$AA$5:$AA$304,MATCH($B17,Drain_Register!$A$5:$A$304,0)),IFERROR(INDEX(RW_Register!$AG$5:$AG$304,MATCH($B17,RW_Register!$A$5:$A$304,0)),IFERROR(INDEX(Other_Register!$W$5:$W$304,MATCH($B17,Other_Register!$A$5:$A$304,0)),0)))) | P17: =IF($B17="","",IF(F17="","ID not found",IF(I17<>"Approved","WARNING: status is "&I17,IF(D17="","Enter length / qty","OK"))))
E18: =IF($B18="","",IF(F18="Others",IFERROR(INDEX(Other_Register!$S$5:$S$304,MATCH($B18,Other_Register!$A$5:$A$304,0)),""),IF(F18="", "","m"))) | F18: =IF($B18="","",IF(ISNUMBER(MATCH($B18,Drain_Register!$A$5:$A$304,0)),"Drain",IF(ISNUMBER(MATCH($B18,RW_Register!$A$5:$A$304,0)),"Ret. Wall",IF(ISNUMBER(MATCH($B18,Other_Register!$A$5:$A$304,0)),"Others","")))) | G18: =IF($B18="","",IFERROR(INDEX(Drain_Register!$B$5:$B$304,MATCH($B18,Drain_Register!$A$5:$A$304,0)),IFERROR(INDEX(RW_Register!$B$5:$B$304,MATCH($B18,RW_Register!$A$5:$A$304,0)),IFERROR(INDEX(Other_Register!$B$5:$B$304,MATCH($B18,Other_Register!$A$5:$A$304,0)),"ID not found - check spelling")))) | H18: =IF($B18="","",IFERROR(INDEX(Drain_Register!$R$5:$R$304,MATCH($B18,Drain_Register!$A$5:$A$304,0)),IFERROR(INDEX(RW_Register!$X$5:$X$304,MATCH($B18,RW_Register!$A$5:$A$304,0)),IFERROR(INDEX(Other_Register!$M$5:$M$304,MATCH($B18,Other_Register!$A$5:$A$304,0)),"")))) | I18: =IF($B18="","",IFERROR(INDEX(Drain_Register!$S$5:$S$304,MATCH($B18,Drain_Register!$A$5:$A$304,0)),IFERROR(INDEX(RW_Register!$Y$5:$Y$304,MATCH($B18,RW_Register!$A$5:$A$304,0)),IFERROR(INDEX(Other_Register!$N$5:$N$304,MATCH($B18,Other_Register!$A$5:$A$304,0)),"")))) | J18: =IF($B18="","",IFERROR(INDEX(Drain_Register!$T$5:$T$304,MATCH($B18,Drain_Register!$A$5:$A$304,0)),IFERROR(INDEX(RW_Register!$Z$5:$Z$304,MATCH($B18,RW_Register!$A$5:$A$304,0)),IFERROR(INDEX(Other_Register!$O$5:$O$304,MATCH($B18,Other_Register!$A$5:$A$304,0)),"")))) | K18: =IF($B18="","",IFERROR(INDEX(Drain_Register!$U$5:$U$304,MATCH($B18,Drain_Register!$A$5:$A$304,0)),IFERROR(INDEX(RW_Register!$AA$5:$AA$304,MATCH($B18,RW_Register!$A$5:$A$304,0)),IFERROR(INDEX(Other_Register!$P$5:$P$304,MATCH($B18,Other_Register!$A$5:$A$304,0)),"")))) | L18: =IF(OR($B18="",$D18=""),"",$D18*IFERROR(INDEX(Drain_Register!$X$5:$X$304,MATCH($B18,Drain_Register!$A$5:$A$304,0)),IFERROR(INDEX(RW_Register!$AD$5:$AD$304,MATCH($B18,RW_Register!$A$5:$A$304,0)),IFERROR(INDEX(Other_Register!$T$5:$T$304,MATCH($B18,Other_Register!$A$5:$A$304,0)),0)))) | M18: =IF(OR($B18="",$D18=""),"",$D18*IFERROR(INDEX(Drain_Register!$Y$5:$Y$304,MATCH($B18,Drain_Register!$A$5:$A$304,0)),IFERROR(INDEX(RW_Register!$AE$5:$AE$304,MATCH($B18,RW_Register!$A$5:$A$304,0)),IFERROR(INDEX(Other_Register!$U$5:$U$304,MATCH($B18,Other_Register!$A$5:$A$304,0)),0)))/1000) | N18: =IF(OR($B18="",$D18=""),"",$D18*IFERROR(INDEX(Drain_Register!$Z$5:$Z$304,MATCH($B18,Drain_Register!$A$5:$A$304,0)),IFERROR(INDEX(RW_Register!$AF$5:$AF$304,MATCH($B18,RW_Register!$A$5:$A$304,0)),IFERROR(INDEX(Other_Register!$V$5:$V$304,MATCH($B18,Other_Register!$A$5:$A$304,0)),0)))) | O18: =IF(OR($B18="",$D18=""),"",$D18*IFERROR(INDEX(Drain_Register!$AA$5:$AA$304,MATCH($B18,Drain_Register!$A$5:$A$304,0)),IFERROR(INDEX(RW_Register!$AG$5:$AG$304,MATCH($B18,RW_Register!$A$5:$A$304,0)),IFERROR(INDEX(Other_Register!$W$5:$W$304,MATCH($B18,Other_Register!$A$5:$A$304,0)),0)))) | P18: =IF($B18="","",IF(F18="","ID not found",IF(I18<>"Approved","WARNING: status is "&I18,IF(D18="","Enter length / qty","OK"))))
E19: =IF($B19="","",IF(F19="Others",IFERROR(INDEX(Other_Register!$S$5:$S$304,MATCH($B19,Other_Register!$A$5:$A$304,0)),""),IF(F19="", "","m"))) | F19: =IF($B19="","",IF(ISNUMBER(MATCH($B19,Drain_Register!$A$5:$A$304,0)),"Drain",IF(ISNUMBER(MATCH($B19,RW_Register!$A$5:$A$304,0)),"Ret. Wall",IF(ISNUMBER(MATCH($B19,Other_Register!$A$5:$A$304,0)),"Others","")))) | G19: =IF($B19="","",IFERROR(INDEX(Drain_Register!$B$5:$B$304,MATCH($B19,Drain_Register!$A$5:$A$304,0)),IFERROR(INDEX(RW_Register!$B$5:$B$304,MATCH($B19,RW_Register!$A$5:$A$304,0)),IFERROR(INDEX(Other_Register!$B$5:$B$304,MATCH($B19,Other_Register!$A$5:$A$304,0)),"ID not found - check spelling")))) | H19: =IF($B19="","",IFERROR(INDEX(Drain_Register!$R$5:$R$304,MATCH($B19,Drain_Register!$A$5:$A$304,0)),IFERROR(INDEX(RW_Register!$X$5:$X$304,MATCH($B19,RW_Register!$A$5:$A$304,0)),IFERROR(INDEX(Other_Register!$M$5:$M$304,MATCH($B19,Other_Register!$A$5:$A$304,0)),"")))) | I19: =IF($B19="","",IFERROR(INDEX(Drain_Register!$S$5:$S$304,MATCH($B19,Drain_Register!$A$5:$A$304,0)),IFERROR(INDEX(RW_Register!$Y$5:$Y$304,MATCH($B19,RW_Register!$A$5:$A$304,0)),IFERROR(INDEX(Other_Register!$N$5:$N$304,MATCH($B19,Other_Register!$A$5:$A$304,0)),"")))) | J19: =IF($B19="","",IFERROR(INDEX(Drain_Register!$T$5:$T$304,MATCH($B19,Drain_Register!$A$5:$A$304,0)),IFERROR(INDEX(RW_Register!$Z$5:$Z$304,MATCH($B19,RW_Register!$A$5:$A$304,0)),IFERROR(INDEX(Other_Register!$O$5:$O$304,MATCH($B19,Other_Register!$A$5:$A$304,0)),"")))) | K19: =IF($B19="","",IFERROR(INDEX(Drain_Register!$U$5:$U$304,MATCH($B19,Drain_Register!$A$5:$A$304,0)),IFERROR(INDEX(RW_Register!$AA$5:$AA$304,MATCH($B19,RW_Register!$A$5:$A$304,0)),IFERROR(INDEX(Other_Register!$P$5:$P$304,MATCH($B19,Other_Register!$A$5:$A$304,0)),"")))) | L19: =IF(OR($B19="",$D19=""),"",$D19*IFERROR(INDEX(Drain_Register!$X$5:$X$304,MATCH($B19,Drain_Register!$A$5:$A$304,0)),IFERROR(INDEX(RW_Register!$AD$5:$AD$304,MATCH($B19,RW_Register!$A$5:$A$304,0)),IFERROR(INDEX(Other_Register!$T$5:$T$304,MATCH($B19,Other_Register!$A$5:$A$304,0)),0)))) | M19: =IF(OR($B19="",$D19=""),"",$D19*IFERROR(INDEX(Drain_Register!$Y$5:$Y$304,MATCH($B19,Drain_Register!$A$5:$A$304,0)),IFERROR(INDEX(RW_Register!$AE$5:$AE$304,MATCH($B19,RW_Register!$A$5:$A$304,0)),IFERROR(INDEX(Other_Register!$U$5:$U$304,MATCH($B19,Other_Register!$A$5:$A$304,0)),0)))/1000) | N19: =IF(OR($B19="",$D19=""),"",$D19*IFERROR(INDEX(Drain_Register!$Z$5:$Z$304,MATCH($B19,Drain_Register!$A$5:$A$304,0)),IFERROR(INDEX(RW_Register!$AF$5:$AF$304,MATCH($B19,RW_Register!$A$5:$A$304,0)),IFERROR(INDEX(Other_Register!$V$5:$V$304,MATCH($B19,Other_Register!$A$5:$A$304,0)),0)))) | O19: =IF(OR($B19="",$D19=""),"",$D19*IFERROR(INDEX(Drain_Register!$AA$5:$AA$304,MATCH($B19,Drain_Register!$A$5:$A$304,0)),IFERROR(INDEX(RW_Register!$AG$5:$AG$304,MATCH($B19,RW_Register!$A$5:$A$304,0)),IFERROR(INDEX(Other_Register!$W$5:$W$304,MATCH($B19,Other_Register!$A$5:$A$304,0)),0)))) | P19: =IF($B19="","",IF(F19="","ID not found",IF(I19<>"Approved","WARNING: status is "&I19,IF(D19="","Enter length / qty","OK"))))
E20: =IF($B20="","",IF(F20="Others",IFERROR(INDEX(Other_Register!$S$5:$S$304,MATCH($B20,Other_Register!$A$5:$A$304,0)),""),IF(F20="", "","m"))) | F20: =IF($B20="","",IF(ISNUMBER(MATCH($B20,Drain_Register!$A$5:$A$304,0)),"Drain",IF(ISNUMBER(MATCH($B20,RW_Register!$A$5:$A$304,0)),"Ret. Wall",IF(ISNUMBER(MATCH($B20,Other_Register!$A$5:$A$304,0)),"Others","")))) | G20: =IF($B20="","",IFERROR(INDEX(Drain_Register!$B$5:$B$304,MATCH($B20,Drain_Register!$A$5:$A$304,0)),IFERROR(INDEX(RW_Register!$B$5:$B$304,MATCH($B20,RW_Register!$A$5:$A$304,0)),IFERROR(INDEX(Other_Register!$B$5:$B$304,MATCH($B20,Other_Register!$A$5:$A$304,0)),"ID not found - check spelling")))) | H20: =IF($B20="","",IFERROR(INDEX(Drain_Register!$R$5:$R$304,MATCH($B20,Drain_Register!$A$5:$A$304,0)),IFERROR(INDEX(RW_Register!$X$5:$X$304,MATCH($B20,RW_Register!$A$5:$A$304,0)),IFERROR(INDEX(Other_Register!$M$5:$M$304,MATCH($B20,Other_Register!$A$5:$A$304,0)),"")))) | I20: =IF($B20="","",IFERROR(INDEX(Drain_Register!$S$5:$S$304,MATCH($B20,Drain_Register!$A$5:$A$304,0)),IFERROR(INDEX(RW_Register!$Y$5:$Y$304,MATCH($B20,RW_Register!$A$5:$A$304,0)),IFERROR(INDEX(Other_Register!$N$5:$N$304,MATCH($B20,Other_Register!$A$5:$A$304,0)),"")))) | J20: =IF($B20="","",IFERROR(INDEX(Drain_Register!$T$5:$T$304,MATCH($B20,Drain_Register!$A$5:$A$304,0)),IFERROR(INDEX(RW_Register!$Z$5:$Z$304,MATCH($B20,RW_Register!$A$5:$A$304,0)),IFERROR(INDEX(Other_Register!$O$5:$O$304,MATCH($B20,Other_Register!$A$5:$A$304,0)),"")))) | K20: =IF($B20="","",IFERROR(INDEX(Drain_Register!$U$5:$U$304,MATCH($B20,Drain_Register!$A$5:$A$304,0)),IFERROR(INDEX(RW_Register!$AA$5:$AA$304,MATCH($B20,RW_Register!$A$5:$A$304,0)),IFERROR(INDEX(Other_Register!$P$5:$P$304,MATCH($B20,Other_Register!$A$5:$A$304,0)),"")))) | L20: =IF(OR($B20="",$D20=""),"",$D20*IFERROR(INDEX(Drain_Register!$X$5:$X$304,MATCH($B20,Drain_Register!$A$5:$A$304,0)),IFERROR(INDEX(RW_Register!$AD$5:$AD$304,MATCH($B20,RW_Register!$A$5:$A$304,0)),IFERROR(INDEX(Other_Register!$T$5:$T$304,MATCH($B20,Other_Register!$A$5:$A$304,0)),0)))) | M20: =IF(OR($B20="",$D20=""),"",$D20*IFERROR(INDEX(Drain_Register!$Y$5:$Y$304,MATCH($B20,Drain_Register!$A$5:$A$304,0)),IFERROR(INDEX(RW_Register!$AE$5:$AE$304,MATCH($B20,RW_Register!$A$5:$A$304,0)),IFERROR(INDEX(Other_Register!$U$5:$U$304,MATCH($B20,Other_Register!$A$5:$A$304,0)),0)))/1000) | N20: =IF(OR($B20="",$D20=""),"",$D20*IFERROR(INDEX(Drain_Register!$Z$5:$Z$304,MATCH($B20,Drain_Register!$A$5:$A$304,0)),IFERROR(INDEX(RW_Register!$AF$5:$AF$304,MATCH($B20,RW_Register!$A$5:$A$304,0)),IFERROR(INDEX(Other_Register!$V$5:$V$304,MATCH($B20,Other_Register!$A$5:$A$304,0)),0)))) | O20: =IF(OR($B20="",$D20=""),"",$D20*IFERROR(INDEX(Drain_Register!$AA$5:$AA$304,MATCH($B20,Drain_Register!$A$5:$A$304,0)),IFERROR(INDEX(RW_Register!$AG$5:$AG$304,MATCH($B20,RW_Register!$A$5:$A$304,0)),IFERROR(INDEX(Other_Register!$W$5:$W$304,MATCH($B20,Other_Register!$A$5:$A$304,0)),0)))) | P20: =IF($B20="","",IF(F20="","ID not found",IF(I20<>"Approved","WARNING: status is "&I20,IF(D20="","Enter length / qty","OK"))))
E21: =IF($B21="","",IF(F21="Others",IFERROR(INDEX(Other_Register!$S$5:$S$304,MATCH($B21,Other_Register!$A$5:$A$304,0)),""),IF(F21="", "","m"))) | F21: =IF($B21="","",IF(ISNUMBER(MATCH($B21,Drain_Register!$A$5:$A$304,0)),"Drain",IF(ISNUMBER(MATCH($B21,RW_Register!$A$5:$A$304,0)),"Ret. Wall",IF(ISNUMBER(MATCH($B21,Other_Register!$A$5:$A$304,0)),"Others","")))) | G21: =IF($B21="","",IFERROR(INDEX(Drain_Register!$B$5:$B$304,MATCH($B21,Drain_Register!$A$5:$A$304,0)),IFERROR(INDEX(RW_Register!$B$5:$B$304,MATCH($B21,RW_Register!$A$5:$A$304,0)),IFERROR(INDEX(Other_Register!$B$5:$B$304,MATCH($B21,Other_Register!$A$5:$A$304,0)),"ID not found - check spelling")))) | H21: =IF($B21="","",IFERROR(INDEX(Drain_Register!$R$5:$R$304,MATCH($B21,Drain_Register!$A$5:$A$304,0)),IFERROR(INDEX(RW_Register!$X$5:$X$304,MATCH($B21,RW_Register!$A$5:$A$304,0)),IFERROR(INDEX(Other_Register!$M$5:$M$304,MATCH($B21,Other_Register!$A$5:$A$304,0)),"")))) | I21: =IF($B21="","",IFERROR(INDEX(Drain_Register!$S$5:$S$304,MATCH($B21,Drain_Register!$A$5:$A$304,0)),IFERROR(INDEX(RW_Register!$Y$5:$Y$304,MATCH($B21,RW_Register!$A$5:$A$304,0)),IFERROR(INDEX(Other_Register!$N$5:$N$304,MATCH($B21,Other_Register!$A$5:$A$304,0)),"")))) | J21: =IF($B21="","",IFERROR(INDEX(Drain_Register!$T$5:$T$304,MATCH($B21,Drain_Register!$A$5:$A$304,0)),IFERROR(INDEX(RW_Register!$Z$5:$Z$304,MATCH($B21,RW_Register!$A$5:$A$304,0)),IFERROR(INDEX(Other_Register!$O$5:$O$304,MATCH($B21,Other_Register!$A$5:$A$304,0)),"")))) | K21: =IF($B21="","",IFERROR(INDEX(Drain_Register!$U$5:$U$304,MATCH($B21,Drain_Register!$A$5:$A$304,0)),IFERROR(INDEX(RW_Register!$AA$5:$AA$304,MATCH($B21,RW_Register!$A$5:$A$304,0)),IFERROR(INDEX(Other_Register!$P$5:$P$304,MATCH($B21,Other_Register!$A$5:$A$304,0)),"")))) | L21: =IF(OR($B21="",$D21=""),"",$D21*IFERROR(INDEX(Drain_Register!$X$5:$X$304,MATCH($B21,Drain_Register!$A$5:$A$304,0)),IFERROR(INDEX(RW_Register!$AD$5:$AD$304,MATCH($B21,RW_Register!$A$5:$A$304,0)),IFERROR(INDEX(Other_Register!$T$5:$T$304,MATCH($B21,Other_Register!$A$5:$A$304,0)),0)))) | M21: =IF(OR($B21="",$D21=""),"",$D21*IFERROR(INDEX(Drain_Register!$Y$5:$Y$304,MATCH($B21,Drain_Register!$A$5:$A$304,0)),IFERROR(INDEX(RW_Register!$AE$5:$AE$304,MATCH($B21,RW_Register!$A$5:$A$304,0)),IFERROR(INDEX(Other_Register!$U$5:$U$304,MATCH($B21,Other_Register!$A$5:$A$304,0)),0)))/1000) | N21: =IF(OR($B21="",$D21=""),"",$D21*IFERROR(INDEX(Drain_Register!$Z$5:$Z$304,MATCH($B21,Drain_Register!$A$5:$A$304,0)),IFERROR(INDEX(RW_Register!$AF$5:$AF$304,MATCH($B21,RW_Register!$A$5:$A$304,0)),IFERROR(INDEX(Other_Register!$V$5:$V$304,MATCH($B21,Other_Register!$A$5:$A$304,0)),0)))) | O21: =IF(OR($B21="",$D21=""),"",$D21*IFERROR(INDEX(Drain_Register!$AA$5:$AA$304,MATCH($B21,Drain_Register!$A$5:$A$304,0)),IFERROR(INDEX(RW_Register!$AG$5:$AG$304,MATCH($B21,RW_Register!$A$5:$A$304,0)),IFERROR(INDEX(Other_Register!$W$5:$W$304,MATCH($B21,Other_Register!$A$5:$A$304,0)),0)))) | P21: =IF($B21="","",IF(F21="","ID not found",IF(I21<>"Approved","WARNING: status is "&I21,IF(D21="","Enter length / qty","OK"))))
